<?xml version="1.0" ?>
<!-- =================================================================================== -->
<!-- |    This document was autogenerated by xacro from rosbot_xl.urdf.xacro           | -->
<!-- |    EDITING THIS FILE BY HAND IS NOT RECOMMENDED                                 | -->
<!-- =================================================================================== -->
<robot name="rosbot_xl">
  <link name="base_link"/>
  <joint name="base_to_body_joint" type="fixed">
    <origin rpy="0.0 0.0 0.0" xyz="0.0 0.0 0.048"/>
    <parent link="base_link"/>
    <child link="body_link"/>
  </joint>
  <link name="body_link">
    <visual>
      <geometry>
        <mesh filename="file:///ros2_ws/install/rosbot_xl_description/share/rosbot_xl_description/meshes/body.dae" scale="1 1 1"/>
      </geometry>
      <origin rpy="0.0 0.0 0.0" xyz="0.0 0.0 0.0"/>
    </visual>
    <collision>
      <geometry>
        <mesh filename="file:///ros2_ws/install/rosbot_xl_description/share/rosbot_xl_description/meshes/body_colision.stl" scale="1 1 1"/>
      </geometry>
      <origin rpy="0.0 0.0 0.0" xyz="0.0 0.0 0.0"/>
    </collision>
    <inertial>
      <mass value="3.5"/>
      <origin rpy="0.0 0.0 0.0" xyz="0.0 0.0 0.0358"/>
      <inertia ixx="0.01393" ixy="-0.000020968097" ixz="0.000010399694" iyy="0.01081" iyz="0.000059372953" izz="0.02048"/>
    </inertial>
  </link>
  <joint name="body_to_cover_joint" type="fixed">
    <origin rpy="0.0 0.0 0.0" xyz="0.0 0.0 0.08345"/>
    <parent link="body_link"/>
    <child link="cover_link"/>
  </joint>
  <link name="cover_link"/>
  <joint name="body_to_imu_joint" type="fixed">
    <origin rpy="3.14159 0.0 0.0" xyz="-0.1369 -0.0419 0.0370"/>
    <parent link="body_link"/>
    <child link="imu_link"/>
  </joint>
  <link name="imu_link"/>
  <joint name="fl_wheel_joint" type="continuous">
    <parent link="body_link"/>
    <child link="fl_wheel_link"/>
    <origin rpy="0.0 0.0 0.0" xyz="0.085 0.124 0.0"/>
    <axis xyz="0.0 1.0 0.0"/>
    <limit effort="1.27" velocity="21.0"/>
    <dynamics damping="0.001" friction="0.001"/>
  </joint>
  <link name="fl_wheel_link">
    <visual>
      <geometry>
        <mesh filename="file:///ros2_ws/install/rosbot_xl_description/share/rosbot_xl_description/meshes/wheel_b.dae" scale="1 1 1"/>
      </geometry>
      <origin rpy="0.0 0.0 3.141592653589793" xyz="0.0 0.0 0.0"/>
    </visual>
    <collision>
      <geometry>
        <cylinder length="0.036" radius="0.048"/>
      </geometry>
      <origin rpy="1.5707963267948966 0.0 0.0" xyz="0.0 0.0 0.0"/>
    </collision>
    <inertial>
      <mass value="0.051"/>
      <inertia ixx="5.0587413e-05" ixy="0.0" ixz="0.0" iyy="8.5933192e-05" iyz="0.0" izz="5.0587829e-05"/>
    </inertial>
  </link>
  <gazebo reference="fl_wheel_link" xmlns:ignition="http://ignitionrobotics.org/schema">
    <collision>
      <surface>
        <friction>
          <ode>
            <mu>1.0</mu>
            <mu2>0.0</mu2>
            <fdir1 ignition:expressed_in="base_link">1 -1 0</fdir1>
          </ode>
        </friction>
      </surface>
    </collision>
  </gazebo>
  <joint name="fr_wheel_joint" type="continuous">
    <parent link="body_link"/>
    <child link="fr_wheel_link"/>
    <origin rpy="0.0 0.0 0.0" xyz="0.085 -0.124 0.0"/>
    <axis xyz="0.0 1.0 0.0"/>
    <limit effort="1.27" velocity="21.0"/>
    <dynamics damping="0.001" friction="0.001"/>
  </joint>
  <link name="fr_wheel_link">
    <visual>
      <geometry>
        <mesh filename="file:///ros2_ws/install/rosbot_xl_description/share/rosbot_xl_description/meshes/wheel_a.dae" scale="1 1 1"/>
      </geometry>
      <origin rpy="0.0 0.0 3.141592653589793" xyz="0.0 0.0 0.0"/>
    </visual>
    <collision>
      <geometry>
        <cylinder length="0.036" radius="0.048"/>
      </geometry>
      <origin rpy="1.5707963267948966 0.0 0.0" xyz="0.0 0.0 0.0"/>
    </collision>
    <inertial>
      <mass value="0.051"/>
      <inertia ixx="5.0587413e-05" ixy="0.0" ixz="0.0" iyy="8.5933192e-05" iyz="0.0" izz="5.0587829e-05"/>
    </inertial>
  </link>
  <gazebo reference="fr_wheel_link" xmlns:ignition="http://ignitionrobotics.org/schema">
    <collision>
      <surface>
        <friction>
          <ode>
            <mu>1.0</mu>
            <mu2>0.0</mu2>
            <fdir1 ignition:expressed_in="base_link">1 1 0</fdir1>
          </ode>
        </friction>
      </surface>
    </collision>
  </gazebo>
  <joint name="rl_wheel_joint" type="continuous">
    <parent link="body_link"/>
    <child link="rl_wheel_link"/>
    <origin rpy="0.0 0.0 0.0" xyz="-0.085 0.124 0.0"/>
    <axis xyz="0.0 1.0 0.0"/>
    <limit effort="1.27" velocity="21.0"/>
    <dynamics damping="0.001" friction="0.001"/>
  </joint>
  <link name="rl_wheel_link">
    <visual>
      <geometry>
        <mesh filename="file:///ros2_ws/install/rosbot_xl_description/share/rosbot_xl_description/meshes/wheel_a.dae" scale="1 1 1"/>
      </geometry>
      <origin rpy="0.0 0.0 0.0" xyz="0.0 0.0 0.0"/>
    </visual>
    <collision>
      <geometry>
        <cylinder length="0.036" radius="0.048"/>
      </geometry>
      <origin rpy="1.5707963267948966 0.0 0.0" xyz="0.0 0.0 0.0"/>
    </collision>
    <inertial>
      <mass value="0.051"/>
      <inertia ixx="5.0587413e-05" ixy="0.0" ixz="0.0" iyy="8.5933192e-05" iyz="0.0" izz="5.0587829e-05"/>
    </inertial>
  </link>
  <gazebo reference="rl_wheel_link" xmlns:ignition="http://ignitionrobotics.org/schema">
    <collision>
      <surface>
        <friction>
          <ode>
            <mu>1.0</mu>
            <mu2>0.0</mu2>
            <fdir1 ignition:expressed_in="base_link">1 1 0</fdir1>
          </ode>
        </friction>
      </surface>
    </collision>
  </gazebo>
  <joint name="rr_wheel_joint" type="continuous">
    <parent link="body_link"/>
    <child link="rr_wheel_link"/>
    <origin rpy="0.0 0.0 0.0" xyz="-0.085 -0.124 0.0"/>
    <axis xyz="0.0 1.0 0.0"/>
    <limit effort="1.27" velocity="21.0"/>
    <dynamics damping="0.001" friction="0.001"/>
  </joint>
  <link name="rr_wheel_link">
    <visual>
      <geometry>
        <mesh filename="file:///ros2_ws/install/rosbot_xl_description/share/rosbot_xl_description/meshes/wheel_b.dae" scale="1 1 1"/>
      </geometry>
      <origin rpy="0.0 0.0 0.0" xyz="0.0 0.0 0.0"/>
    </visual>
    <collision>
      <geometry>
        <cylinder length="0.036" radius="0.048"/>
      </geometry>
      <origin rpy="1.5707963267948966 0.0 0.0" xyz="0.0 0.0 0.0"/>
    </collision>
    <inertial>
      <mass value="0.051"/>
      <inertia ixx="5.0587413e-05" ixy="0.0" ixz="0.0" iyy="8.5933192e-05" iyz="0.0" izz="5.0587829e-05"/>
    </inertial>
  </link>
  <gazebo reference="rr_wheel_link" xmlns:ignition="http://ignitionrobotics.org/schema">
    <collision>
      <surface>
        <friction>
          <ode>
            <mu>1.0</mu>
            <mu2>0.0</mu2>
            <fdir1 ignition:expressed_in="base_link">1 -1 0</fdir1>
          </ode>
        </friction>
      </surface>
    </collision>
  </gazebo>
  <ros2_control name="wheels" type="system">
    <hardware>
    </hardware>
    <joint name="fl_wheel_joint">
      <command_interface name="velocity"/>
      <state_interface name="position"/>
      <state_interface name="velocity"/>
    </joint>
    <joint name="fr_wheel_joint">
      <command_interface name="velocity"/>
      <state_interface name="position"/>
      <state_interface name="velocity"/>
    </joint>
    <joint name="rl_wheel_joint">
      <command_interface name="velocity"/>
      <state_interface name="position"/>
      <state_interface name="velocity"/>
    </joint>
    <joint name="rr_wheel_joint">
      <command_interface name="velocity"/>
      <state_interface name="position"/>
      <state_interface name="velocity"/>
    </joint>
  </ros2_control>
  <joint name="body_to_antenna_connector_joint" type="fixed">
    <origin rpy="0.0 0.0 0.0" xyz="-0.155 -0.055 0.065"/>
    <parent link="body_link"/>
    <child link="antenna_connector_link"/>
  </joint>
  <link name="antenna_connector_link">
    <visual>
      <geometry>
        <mesh filename="file:///ros2_ws/install/rosbot_xl_description/share/rosbot_xl_description/meshes/components/antenna_connector.dae" scale="1 1 1"/>
      </geometry>
      <origin rpy="0.0 0.0 0.0" xyz="0.0 0.0 0.0"/>
    </visual>
  </link>
  <joint name="antenna_connector_to_antenna_joint" type="fixed">
    <origin rpy="0.0 0.0 0.0" xyz="-0.013 0.0 0.008"/>
    <parent link="antenna_connector_link"/>
    <child link="antenna_link"/>
  </joint>
  <link name="antenna_link">
    <visual>
      <geometry>
        <mesh filename="file:///ros2_ws/install/rosbot_xl_description/share/rosbot_xl_description/meshes/components/antenna.dae" scale="1 1 1"/>
      </geometry>
      <origin rpy="0.0 0.0 0.0" xyz="0.0 0.0 0.0"/>
    </visual>
    <collision>
      <geometry>
        <cylinder length="0.1" radius="0.0052"/>
      </geometry>
      <origin rpy="0.0 0.0 0.0" xyz="0.0 0.0 0.05"/>
    </collision>
  </link>
  <!-- INCLUDE LIDAR -->
  <!-- use_gpu has to be set to true, CPU lidar doesn't work in ignition -
    https://github.com/gazebosim/gz-sensors/issues/26 -->
  <joint name="cover_to_velodyne_puck_joint" type="fixed">
    <origin rpy="0.0 0.0 0.0" xyz="0.0 0.0 0.0"/>
    <parent link="cover_link"/>
    <child link="velodyne_puck_link"/>
  </joint>
  <link name="velodyne_puck_link">
    <visual>
      <origin rpy="0.0 0.0 0.0" xyz="0.0 0.0 0.0"/>
      <geometry>
        <mesh filename="file:///ros2_ws/install/ros_components_description/share/ros_components_description/meshes/velodyne_puck.dae"/>
      </geometry>
    </visual>
    <collision>
      <origin rpy="0.0 0.0 0.0" xyz="0.0 0.0 0.036"/>
      <geometry>
        <cylinder length="0.072" radius="0.0515"/>
      </geometry>
    </collision>
    <inertial>
      <origin rpy="0.0 0.0 0.0" xyz="0.0 0.0 0.036"/>
      <mass value="0.830"/>
      <inertia ixx="0.001111" ixy="0.0" ixz="0.0" iyy="0.001109" iyz="0.0" izz="0.001493"/>
    </inertial>
  </link>
  <joint name="velodyne_puck_to_velodyne_joint" type="fixed">
    <origin rpy="0.0 0.0 0.0" xyz="0.0 0.0 0.0378"/>
    <parent link="velodyne_puck_link"/>
    <child link="velodyne"/>
  </joint>
  <link name="velodyne"/>
  <gazebo reference="velodyne">
    <sensor name="velodyne_puck_sensor" type="gpu_ray">
      <visualize>false</visualize>
      <update_rate>10.0</update_rate>
      <ray>
        <scan>
          <horizontal>
            <samples>900</samples>
            <resolution>1</resolution>
            <min_angle>-3.141592653589793</min_angle>
            <max_angle>3.141592653589793</max_angle>
          </horizontal>
          <vertical>
            <samples>16</samples>
            <resolution>1</resolution>
            <min_angle>-0.2617993877991494</min_angle>
            <max_angle>0.2617993877991494</max_angle>
          </vertical>
        </scan>
        <range>
          <min>0.4</min>
          <max>100.0</max>
          <resolution>0.003</resolution>
        </range>
        <noise>
          <type>gaussian</type>
          <mean>0.0</mean>
          <stddev>0.0008</stddev>
        </noise>
      </ray>
    </sensor>
  </gazebo>
  <!-- INCLUDE CAMERA MOUNT -->
</robot>
