<?xml version="1.0" ?>
<!-- =================================================================================== -->
<!-- |    This document was autogenerated by xacro from rosbot_xl.urdf.xacro           | -->
<!-- |    EDITING THIS FILE BY HAND IS NOT RECOMMENDED                                 | -->
<!-- =================================================================================== -->
<robot name="rosbot_xl">
  <link name="base_link"/>
  <joint name="base_to_body_joint" type="fixed">
    <origin rpy="0.0 0.0 0.0" xyz="0.0 0.0 0.048"/>
    <parent link="base_link"/>
    <child link="body_link"/>
  </joint>
  <link name="body_link">
    <visual>
      <geometry>
        <mesh filename="file:///ros2_ws/install/rosbot_xl_description/share/rosbot_xl_description/meshes/body.dae" scale="1 1 1"/>
      </geometry>
      <origin rpy="0.0 0.0 0.0" xyz="0.0 0.0 0.0"/>
    </visual>
    <collision>
      <geometry>
        <mesh filename="file:///ros2_ws/install/rosbot_xl_description/share/rosbot_xl_description/meshes/body_colision.stl" scale="1 1 1"/>
      </geometry>
      <origin rpy="0.0 0.0 0.0" xyz="0.0 0.0 0.0"/>
    </collision>
    <inertial>
      <mass value="3.5"/>
      <origin rpy="0.0 0.0 0.0" xyz="0.0 0.0 0.0358"/>
      <inertia ixx="0.01393" ixy="-0.000020968097" ixz="0.000010399694" iyy="0.01081" iyz="0.000059372953" izz="0.02048"/>
    </inertial>
  </link>
  <joint name="body_to_cover_joint" type="fixed">
    <origin rpy="0.0 0.0 0.0" xyz="0.0 0.0 0.08345"/>
    <parent link="body_link"/>
    <child link="cover_link"/>
  </joint>
  <link name="cover_link"/>
  <joint name="body_to_imu_joint" type="fixed">
    <origin rpy="3.14159 0.0 0.0" xyz="-0.1369 -0.0419 0.0370"/>
    <parent link="body_link"/>
    <child link="imu_link"/>
  </joint>
  <link name="imu_link"/>
  <joint name="fl_wheel_joint" type="continuous">
    <parent link="body_link"/>
    <child link="fl_wheel_link"/>
    <origin rpy="0.0 0.0 0.0" xyz="0.085 0.124 0.0"/>
    <axis xyz="0.0 1.0 0.0"/>
    <limit effort="1.27" velocity="21.0"/>
    <dynamics damping="0.001" friction="0.001"/>
  </joint>
  <link name="fl_wheel_link">
    <visual>
      <geometry>
        <mesh filename="file:///ros2_ws/install/rosbot_xl_description/share/rosbot_xl_description/meshes/wheel_b.dae" scale="1 1 1"/>
      </geometry>
      <origin rpy="0.0 0.0 3.141592653589793" xyz="0.0 0.0 0.0"/>
    </visual>
    <collision>
      <geometry>
        <cylinder length="0.036" radius="0.048"/>
      </geometry>
      <origin rpy="1.5707963267948966 0.0 0.0" xyz="0.0 0.0 0.0"/>
    </collision>
    <inertial>
      <mass value="0.051"/>
      <inertia ixx="5.0587413e-05" ixy="0.0" ixz="0.0" iyy="8.5933192e-05" iyz="0.0" izz="5.0587829e-05"/>
    </inertial>
  </link>
  <gazebo reference="fl_wheel_link" xmlns:ignition="http://ignitionrobotics.org/schema">
    <collision>
      <surface>
        <friction>
          <ode>
            <mu>1.0</mu>
            <mu2>0.0</mu2>
            <fdir1 ignition:expressed_in="base_link">1 -1 0</fdir1>
          </ode>
        </friction>
      </surface>
    </collision>
  </gazebo>
  <joint name="fr_wheel_joint" type="continuous">
    <parent link="body_link"/>
    <child link="fr_wheel_link"/>
    <origin rpy="0.0 0.0 0.0" xyz="0.085 -0.124 0.0"/>
    <axis xyz="0.0 1.0 0.0"/>
    <limit effort="1.27" velocity="21.0"/>
    <dynamics damping="0.001" friction="0.001"/>
  </joint>
  <link name="fr_wheel_link">
    <visual>
      <geometry>
        <mesh filename="file:///ros2_ws/install/rosbot_xl_description/share/rosbot_xl_description/meshes/wheel_a.dae" scale="1 1 1"/>
      </geometry>
      <origin rpy="0.0 0.0 3.141592653589793" xyz="0.0 0.0 0.0"/>
    </visual>
    <collision>
      <geometry>
        <cylinder length="0.036" radius="0.048"/>
      </geometry>
      <origin rpy="1.5707963267948966 0.0 0.0" xyz="0.0 0.0 0.0"/>
    </collision>
    <inertial>
      <mass value="0.051"/>
      <inertia ixx="5.0587413e-05" ixy="0.0" ixz="0.0" iyy="8.5933192e-05" iyz="0.0" izz="5.0587829e-05"/>
    </inertial>
  </link>
  <gazebo reference="fr_wheel_link" xmlns:ignition="http://ignitionrobotics.org/schema">
    <collision>
      <surface>
        <friction>
          <ode>
            <mu>1.0</mu>
            <mu2>0.0</mu2>
            <fdir1 ignition:expressed_in="base_link">1 1 0</fdir1>
          </ode>
        </friction>
      </surface>
    </collision>
  </gazebo>
  <joint name="rl_wheel_joint" type="continuous">
    <parent link="body_link"/>
    <child link="rl_wheel_link"/>
    <origin rpy="0.0 0.0 0.0" xyz="-0.085 0.124 0.0"/>
    <axis xyz="0.0 1.0 0.0"/>
    <limit effort="1.27" velocity="21.0"/>
    <dynamics damping="0.001" friction="0.001"/>
  </joint>
  <link name="rl_wheel_link">
    <visual>
      <geometry>
        <mesh filename="file:///ros2_ws/install/rosbot_xl_description/share/rosbot_xl_description/meshes/wheel_a.dae" scale="1 1 1"/>
      </geometry>
      <origin rpy="0.0 0.0 0.0" xyz="0.0 0.0 0.0"/>
    </visual>
    <collision>
      <geometry>
        <cylinder length="0.036" radius="0.048"/>
      </geometry>
      <origin rpy="1.5707963267948966 0.0 0.0" xyz="0.0 0.0 0.0"/>
    </collision>
    <inertial>
      <mass value="0.051"/>
      <inertia ixx="5.0587413e-05" ixy="0.0" ixz="0.0" iyy="8.5933192e-05" iyz="0.0" izz="5.0587829e-05"/>
    </inertial>
  </link>
  <gazebo reference="rl_wheel_link" xmlns:ignition="http://ignitionrobotics.org/schema">
    <collision>
      <surface>
        <friction>
          <ode>
            <mu>1.0</mu>
            <mu2>0.0</mu2>
            <fdir1 ignition:expressed_in="base_link">1 1 0</fdir1>
          </ode>
        </friction>
      </surface>
    </collision>
  </gazebo>
  <joint name="rr_wheel_joint" type="continuous">
    <parent link="body_link"/>
    <child link="rr_wheel_link"/>
    <origin rpy="0.0 0.0 0.0" xyz="-0.085 -0.124 0.0"/>
    <axis xyz="0.0 1.0 0.0"/>
    <limit effort="1.27" velocity="21.0"/>
    <dynamics damping="0.001" friction="0.001"/>
  </joint>
  <link name="rr_wheel_link">
    <visual>
      <geometry>
        <mesh filename="file:///ros2_ws/install/rosbot_xl_description/share/rosbot_xl_description/meshes/wheel_b.dae" scale="1 1 1"/>
      </geometry>
      <origin rpy="0.0 0.0 0.0" xyz="0.0 0.0 0.0"/>
    </visual>
    <collision>
      <geometry>
        <cylinder length="0.036" radius="0.048"/>
      </geometry>
      <origin rpy="1.5707963267948966 0.0 0.0" xyz="0.0 0.0 0.0"/>
    </collision>
    <inertial>
      <mass value="0.051"/>
      <inertia ixx="5.0587413e-05" ixy="0.0" ixz="0.0" iyy="8.5933192e-05" iyz="0.0" izz="5.0587829e-05"/>
    </inertial>
  </link>
  <gazebo reference="rr_wheel_link" xmlns:ignition="http://ignitionrobotics.org/schema">
    <collision>
      <surface>
        <friction>
          <ode>
            <mu>1.0</mu>
            <mu2>0.0</mu2>
            <fdir1 ignition:expressed_in="base_link">1 -1 0</fdir1>
          </ode>
        </friction>
      </surface>
    </collision>
  </gazebo>
  <ros2_control name="wheels" type="system">
    <hardware>
      <plugin>ign_ros2_control/IgnitionSystem</plugin>
    </hardware>
    <joint name="fl_wheel_joint">
      <command_interface name="velocity"/>
      <state_interface name="position"/>
      <state_interface name="velocity"/>
    </joint>
    <joint name="fr_wheel_joint">
      <command_interface name="velocity"/>
      <state_interface name="position"/>
      <state_interface name="velocity"/>
    </joint>
    <joint name="rl_wheel_joint">
      <command_interface name="velocity"/>
      <state_interface name="position"/>
      <state_interface name="velocity"/>
    </joint>
    <joint name="rr_wheel_joint">
      <command_interface name="velocity"/>
      <state_interface name="position"/>
      <state_interface name="velocity"/>
    </joint>
    <sensor name="imu">
      <state_interface name="orientation.x"/>
      <state_interface name="orientation.y"/>
      <state_interface name="orientation.z"/>
      <state_interface name="orientation.w"/>
      <state_interface name="angular_velocity.x"/>
      <state_interface name="angular_velocity.y"/>
      <state_interface name="angular_velocity.z"/>
      <state_interface name="linear_acceleration.x"/>
      <state_interface name="linear_acceleration.y"/>
      <state_interface name="linear_acceleration.z"/>
    </sensor>
  </ros2_control>
  <gazebo>
    <plugin filename="ign_ros2_control-system" name="ign_ros2_control::IgnitionROS2ControlPlugin">
      <parameters>/ros2_ws/install/rosbot_xl_controller/share/rosbot_xl_controller/config/diff_drive_controller.yaml</parameters>
      <controller_manager_prefix_node_name>simulation</controller_manager_prefix_node_name>
      <ros>
        <remapping>/rosbot_xl_base_controller/cmd_vel_unstamped:=/cmd_vel</remapping>
      </ros>
    </plugin>
  </gazebo>
  <gazebo reference="imu_link">
    <sensor name="imu" type="imu">
      <plugin filename="ignition-gazebo-imu-system" name="ignition::gazebo::systems::Imu"/>
      <always_on>true</always_on>
      <update_rate>25</update_rate>
      <topic>imu/data_raw</topic>
      <visualize>false</visualize>
      <enable_metrics>false</enable_metrics>
      <frame_id>imu_link</frame_id>
      <ignition_frame_id>imu_link</ignition_frame_id>
    </sensor>
  </gazebo>
  <joint name="body_to_antenna_connector_joint" type="fixed">
    <origin rpy="0.0 0.0 0.0" xyz="-0.155 -0.055 0.065"/>
    <parent link="body_link"/>
    <child link="antenna_connector_link"/>
  </joint>
  <link name="antenna_connector_link">
    <visual>
      <geometry>
        <mesh filename="file:///ros2_ws/install/rosbot_xl_description/share/rosbot_xl_description/meshes/components/antenna_connector.dae" scale="1 1 1"/>
      </geometry>
      <origin rpy="0.0 0.0 0.0" xyz="0.0 0.0 0.0"/>
    </visual>
  </link>
  <joint name="antenna_connector_to_antenna_joint" type="fixed">
    <origin rpy="0.0 0.0 0.0" xyz="-0.013 0.0 0.008"/>
    <parent link="antenna_connector_link"/>
    <child link="antenna_link"/>
  </joint>
  <link name="antenna_link">
    <visual>
      <geometry>
        <mesh filename="file:///ros2_ws/install/rosbot_xl_description/share/rosbot_xl_description/meshes/components/antenna.dae" scale="1 1 1"/>
      </geometry>
      <origin rpy="0.0 0.0 0.0" xyz="0.0 0.0 0.0"/>
    </visual>
    <collision>
      <geometry>
        <cylinder length="0.1" radius="0.0052"/>
      </geometry>
      <origin rpy="0.0 0.0 0.0" xyz="0.0 0.0 0.05"/>
    </collision>
  </link>
  <!-- INCLUDE LIDAR -->
  <!-- use_gpu has to be set to true, CPU lidar doesn't work in ignition -
    https://github.com/gazebosim/gz-sensors/issues/26 -->
  <joint name="cover_to_slamtec_rplidar_s1_joint" type="fixed">
    <origin rpy="0.0 0.0 0.0" xyz="0.0 0.0 0.0"/>
    <parent link="cover_link"/>
    <child link="slamtec_rplidar_s1_link"/>
  </joint>
  <link name="slamtec_rplidar_s1_link">
    <visual>
      <origin rpy="0.0 0.0 0.0" xyz="0.0 0.0 0.0"/>
      <geometry>
        <mesh filename="file:///ros2_ws/install/ros_components_description/share/ros_components_description/meshes/slamtec_rplidar_s1.dae"/>
      </geometry>
    </visual>
    <!-- spinning head collision -->
    <collision>
      <origin rpy="0.0 0.0 0.0" xyz="0.0 0.0 0.0255"/>
      <geometry>
        <cylinder length="0.051" radius="0.02775"/>
      </geometry>
    </collision>
    <!-- base collision -->
    <collision>
      <origin rpy="0.0 0.0 0.0" xyz="0.0 0.0 0.00975"/>
      <geometry>
        <box size="0.0555 0.0555 0.0195"/>
      </geometry>
    </collision>
    <inertial>
      <origin rpy="0.0 0.0 0.0" xyz="0.0 0.0 0.02775"/>
      <mass value="0.105"/>
      <inertia ixx="0.000049654" ixy="0.0" ixz="0.0" iyy="0.000049654" iyz="0.0" izz="0.000053884"/>
    </inertial>
  </link>
  <joint name="slamtec_rplidar_s1_to_laser_joint" type="fixed">
    <origin rpy="0.0 0.0 3.141592653589793" xyz="0.0 0.0 0.04"/>
    <parent link="slamtec_rplidar_s1_link"/>
    <child link="laser"/>
  </joint>
  <link name="laser"/>
  <gazebo reference="laser">
    <sensor name="rplidar_s1_sensor" type="gpu_lidar">
      <topic>scan</topic>
      <frame_id>laser</frame_id>
      <ignition_frame_id>laser</ignition_frame_id>
      <update_rate>10.0</update_rate>
      <ray>
        <scan>
          <horizontal>
            <samples>920</samples>
            <resolution>1</resolution>
            <min_angle>-3.141592653589793</min_angle>
            <max_angle>3.141592653589793</max_angle>
          </horizontal>
        </scan>
        <range>
          <min>0.04</min>
          <max>40.0</max>
          <resolution>0.03</resolution>
        </range>
        <noise>
          <type>gaussian</type>
          <mean>0.0</mean>
          <stddev>0.001</stddev>
        </noise>
      </ray>
      <always_on>1</always_on>
      <visualize>false</visualize>
    </sensor>
  </gazebo>
  <gazebo>
    <plugin filename="libignition-gazebo-sensors-system.so" name="ignition::gazebo::systems::Sensors">
      <render_engine>ogre2</render_engine>
    </plugin>
  </gazebo>
  <!-- INCLUDE CAMERA -->
  <!-- INCLUDE CAMERA MOUNT -->
</robot>
